Workbook

Sheet 635
B1: 635 | L1: Full payment | P1: 635 RECEIVABLE FROM ATE CZARINA
B2: Date | E2: Amount | F2: Parking | G2: Agent's Commissions | H2: Remarks | I2: Reservation | K2: Balance | O2: Cleaning Fee | P2: Others | Q2: Receivable Balance | R2: Remarks
I3: Gcash | J3: BDO | L3: BDO | M3: GCASH | N3: Ate CZARINA
B4: Feb | C4: 45941 | D4: 1 | E4: 2000 | I4: 1000 | K4: =E4-I4-L4-M4-N4-J4+F4 -> 0 | N4: 1000 | O4: -500 | Q4: =N4+O4+P4 -> 500
C5: 13-14 | D5: 1 | E5: 2300 | I5: 1000 | K5: =E5-I5-L5-M5-N5-J5+F5 -> 0 | N5: 1300 | O5: -500 | Q5: =Q4+N5+O5+P5 -> 1300
C6: 14-15 | D6: 1 | E6: 2600 | G6: -300 | I6: 500 | K6: =E6-I6-L6-M6-N6-J6+F6 -> 0 | N6: 2100 | O6: -500 | Q6: =Q5+N6+O6+P6 -> 2900
C7: 15-17 | D7: 2 | E7: 5300 | I7: 1500 | K7: =E7-I7-L7-M7-N7-J7+F7 -> 0 | N7: 3800 | O7: -500 | Q7: =Q6+N7+O7+P7 -> 6200
C8: 17-19 | D8: 2 | E8: =4200+1800 -> 6000 | G8: -800 | K8: =E8-I8-L8-M8-N8-J8+F8 -> 0 | M8: 1800 | N8: 4200 | O8: -500 | Q8: =Q7+N8+O8+P8 -> 9900
C9: 19-21 | K9: =E9-I9-L9-M9-N9-J9+F9 -> 0 | Q9: =Q8+N9+O9+P9 -> 9900
C10: 21-22 | D10: 1 | E10: 3350 | F10: 450 | I10: 1450 | K10: =E10-I10-L10-M10-N10-J10+F10 -> 0 | N10: 2350 | O10: -500 | Q10: =Q9+N10+O10+P10 -> 11750
C11: 22-24 | D11: 2 | E11: 4800 | I11: 1300 | K11: =E11-I11-L11-M11-N11-J11+F11 -> 0 | N11: 3500 | O11: -500 | Q11: =Q10+N11+O11+P11 -> 14750
C12: 24-25 | D12: 1 | E12: =2100+350 -> 2450 | I12: 600 | K12: =E12-I12-L12-M12-N12-J12+F12 -> 0 | M12: 1850 | O12: -500 | Q12: =Q11+N12+O12+P12 -> 14250
C13: 25-26 | K13: =E13-I13-L13-M13-N13-J13+F13 -> 0 | Q13: =Q12+N13+O13+P13 -> 14250
C14: 26-27 | D14: 1 | E14: 2650 | I14: 1000 | K14: =E14-I14-L14-M14-N14-J14+F14 -> 0 | N14: 1650 | O14: -500 | Q14: =Q13+N14+O14+P14 -> 15400
C15: 27-28 | K15: =E15-I15-L15-M15-N15-J15+F15 -> 0 | Q15: =Q14+N15+O15+P15 -> 15400
C16: 28-1 | D16: 1 | E16: 2300 | I16: 500 | K16: =E16-I16-L16-M16-N16-J16+F16 -> 0 | M16: 800 | N16: 1000 | O16: -500 | Q16: =Q15+N16+O16+P16 -> 15900
P17: -500 | Q17: =Q16+N17+O17+P17 -> 15400 | R17: General cleaning
P18: -500 | Q18: =Q17+N18+O18+P18 -> 14900 | R18: Laundry
K19: =E19-I19-L19-M19-N19-J19+F19 -> 0 | P19: =-1500+-300 -> -1800 | Q19: =Q18+N19+O19+P19 -> 13100 | R19: heater repair
K20: =E20-I20-L20-M20-N20-J20+F20 -> 0 | P20: -695.5 | Q20: =Q19+N20+O20+P20 -> 12404.5 | R20: supplies
P21: -12404.5 | Q21: =Q20+N21+O21+P21 -> 0
B22: Feb | C22: Total | D22: =sum(D4:D19) -> 13 | E22: =sum(E4:E19) -> 33750 | G22: =sum(G4:G19) -> -1100 | I22: =sum(I4:I19) -> 8850 | J22: =sum(J4:J19) -> 0 | K22: =sum(K4:K19) -> 0 | L22: =sum(L4:L19) -> 0 | M22: =sum(M4:M19) -> 4450 | N22: =sum(N4:N19) -> 20900 | O22: =sum(O4:O19) -> -5000 | P22: =sum(P4:P19) -> -2800 | Q22: =Q21 -> 0
B23: Mar | C23: 45659 | D23: 1 | E23: 3750 | I23: 1000 | K23: =E23-I23-L23-M23-N23-J23+F23 -> 0 | N23: 2750 | O23: -500 | Q23: =N23+O23+P23 -> 2250
C24: 45691 | D24: 1 | E24: =2600+350 -> 2950 | J24: 1200 | K24: =E24-I24-L24-M24-N24-J24+F24 -> 0 | N24: 1750 | O24: -500 | Q24: =Q23+N24+O24+P24 -> 3500
C25: 45721 | K25: =E25-I25-L25-M25-N25-J25+F25 -> 0 | Q25: =Q24+N25+O25+P25 -> 3500
C26: 45783 | D26: 1 | E26: 2000 | I26: 800 | K26: =E26-I26-L26-M26-N26-J26+F26 -> 0 | N26: 1200 | O26: -500 | Q26: =Q25+N26+O26+P26 -> 4200
C27: 45816 | D27: 2 | E27: 3240.1 | H27: airbnb | K27: =E27-I27-L27-M27-N27-J27+F27 -> 0 | L27: 3240.1 | O27: -500 | Q27: =Q26+N27+O27+P27 -> 3700
C28: 45878 | D28: 1 | E28: 3500 | I28: 1000 | K28: =E28-I28-L28-M28-N28-J28+F28 -> 0 | N28: 2500 | O28: -500 | Q28: =Q27+N28+O28+P28 -> 5700
C29: 45910 | K29: =E29-I29-L29-M29-N29-J29+F29 -> 0 | Q29: =Q28+N29+O29+P29 -> 5700
C30: 45941 | D30: 1 | E30: =2100 -> 2100 | F30: 350 | I30: 950 | K30: =E30-I30-L30-M30-N30-J30+F30 -> 0 | N30: 1500 | O30: -500 | Q30: =Q29+N30+O30+P30 -> 6700
C31: 45975 | K31: =E31-I31-L31-M31-N31-J31+F31 -> 0 | Q31: =Q30+N31+O31+P31 -> 6700
C32: 15-16 | D32: 1 | E32: 3000 | I32: 500 | K32: =E32-I32-L32-M32-N32-J32+F32 -> 0 | N32: 2500 | O32: -500 | Q32: =Q31+N32+O32+P32 -> 8700
C33: 16-17 | D33: 1 | E33: 2500 | I33: 1000 | K33: =E33-I33-L33-M33-N33-J33+F33 -> 0 | N33: 1500 | O33: -500 | Q33: =Q32+N33+O33+P33 -> 9700
C34: 17-19 | D34: 2 | E34: 3500 | I34: 1500 | K34: =E34-I34-L34-M34-N34-J34+F34 -> 0 | N34: 2000 | O34: -500 | Q34: =Q33+N34+O34+P34 -> 11200
C35: 19-21 | K35: =E35-I35-L35-M35-N35-J35+F35 -> 0 | O35: -500 | Q35: =Q34+N35+O35+P35 -> 10700 | R35: Jaykath (Mar 21)
C36: 22-23 | D36: 1 | E36: 3500 | I36: 700 | K36: =E36-I36-L36-M36-N36-J36+F36 -> 0 | N36: 2800 | O36: -500 | Q36: =Q35+N36+O36+P36 -> 13000
C37: 23-26 | D37: 3 | E37: =4899+1000 -> 5899 | G37: -899 | I37: 1000 | K37: =E37-I37-L37-M37-N37-J37+F37 -> 0 | N37: 4899 | O37: -500 | Q37: =Q36+N37+O37+P37 -> 17399
C38: 26-27 | K38: =E38-I38-L38-M38-N38-J38+F38 -> 0 | Q38: =Q37+N38+O38+P38 -> 17399
C39: 27-28 | D39: 1 | E39: 2400 | I39: 1500 | K39: =E39-I39-L39-M39-N39-J39+F39 -> 0 | M39: 900 | O39: -500 | Q39: =Q38+N39+O39+P39 -> 16899
C40: 28-29 | E40: 1000 | H40: forfeited | I40: 1000 | K40: =E40-I40-L40-M40-N40-J40+F40 -> 0 | Q40: =Q39+N40+O40+P40 -> 16899
...

Sheet 1931
B1: 1931 BOOKING | L1: Full payment | P1: 1931 RECEIVABLE FROM ATE CZARINA
B2: Date | E2: Amount | F2: Parking | G2: Agent's Commissions | H2: Remarks | I2: Reservation | K2: Balance | O2: Cleaning Fee | P2: Others | Q2: Receivable Balance | R2: Remarks
I3: Gcash | J3: BDO | L3: BDO | M3: GCASH | N3: Ate CZARINA
B4: Jan | C4: 45691 | D4: 1 | E4: 2000 | F4: 450 | I4: 1200 | K4: =E4-I4-L4-M4-N4-J4+F4 -> 0 | M4: 1250 | O4: -500 | Q4: =N4+O4+P4 -> -500
C5: 3-4 | D5: 1 | E5: 2000 | I5: 1000 | K5: =E5-I5-L5-M5-N5-J5+F5 -> 0 | N5: 1000 | O5: -500 | Q5: =Q4+N5+O5+P5 -> 0
C6: 45752 | D6: 1 | E6: 3000 | F6: 450 | G6: =50+400 -> 450 | I6: 1000 | K6: =E6-I6-L6-M6-N6-J6+F6 -> 0 | N6: 2450 | O6: -500 | Q6: =Q5+N6+O6+P6 -> 1950
C7: 5-8 | K7: =E7-I7-L7-M7-N7-J7+F7 -> 0 | Q7: =Q6+N7+O7+P7 -> 1950
C8: 8-9 | D8: 1 | E8: 2000 | I8: 1000 | K8: =E8-I8-L8-M8-N8-J8+F8 -> 0 | N8: 1000 | O8: -500 | Q8: =Q7+N8+O8+P8 -> 2450
C9: 45910 | D9: 1 | E9: 2000 | I9: 1000 | K9: =E9-I9-L9-M9-N9-J9+F9 -> 0 | N9: 1000 | O9: -500 | Q9: =Q8+N9+O9+P9 -> 2950
C10: 45941 | D10: 1 | E10: 2300 | I10: 1000 | K10: =E10-I10-L10-M10-N10-J10+F10 -> 0 | N10: 1300 | O10: -500 | Q10: =Q9+N10+O10+P10 -> 3750
C11: 45973 | D11: 1 | E11: =2500+400 -> 2900 | I11: 1000 | K11: =E11-I11-L11-M11-N11-J11+F11 -> 0 | N11: 1900 | O11: -500 | Q11: =Q10+N11+O11+P11 -> 5150
C12: 46005 | K12: =E12-I12-L12-M12-N12-J12+F12 -> 0 | Q12: =Q11+N12+O12+P12 -> 5150
C13: 14-15 | D13: 1 | E13: 2200 | G13: 400 | I13: 1000 | K13: =E13-I13-L13-M13-N13-J13+F13 -> 0 | N13: 1200 | O13: -500 | Q13: =Q12+N13+O13+P13 -> 5850
C14: 15-16 | D14: 1 | E14: 1800 | I14: 1000 | K14: =E14-I14-L14-M14-N14-J14+F14 -> 0 | N14: 800 | O14: -500 | Q14: =Q13+N14+O14+P14 -> 6150
C15: 16-17 | D15: 1 | E15: 1800 | I15: 1000 | K15: =E15-I15-L15-M15-N15-J15+F15 -> 0 | M15: 800 | O15: -500 | Q15: =Q14+N15+O15+P15 -> 5650
C16: 17-18 | D16: 1 | E16: 2300 | I16: 1000 | K16: =E16-I16-L16-M16-N16-J16+F16 -> 0 | N16: 1300 | O16: -500 | Q16: =Q15+N16+O16+P16 -> 6450
C17: 18-19 | D17: 1 | E17: 2500 | I17: 1000 | K17: =E17-I17-L17-M17-N17-J17+F17 -> 0 | N17: 1500 | O17: -500 | Q17: =Q16+N17+O17+P17 -> 7450
C18: 19-20 | K18: =E18-I18-L18-M18-N18-J18+F18 -> 0 | Q18: =Q17+N18+O18+P18 -> 7450
C19: 20-22 | D19: 2 | E19: 3500 | I19: 1500 | K19: =E19-I19-L19-M19-N19-J19+F19 -> 0 | N19: 2000 | O19: -500 | Q19: =Q18+N19+O19+P19 -> 8950
C20: 22-23 | K20: =E20-I20-L20-M20-N20-J20+F20 -> 0 | Q20: =Q19+N20+O20+P20 -> 8950
C21: 23-24 | D21: 1 | E21: 2000 | I21: 1000 | K21: =E21-I21-L21-M21-N21-J21+F21 -> 0 | N21: 1000 | O21: -500 | Q21: =Q20+N21+O21+P21 -> 9450
C22: 24-25 | D22: 1 | E22: 2300 | I22: 1000 | K22: =E22-I22-L22-M22-N22-J22+F22 -> 0 | N22: 1300 | O22: -500 | Q22: =Q21+N22+O22+P22 -> 10250
C23: 25-26 | D23: 1 | E23: 2500 | I23: 500 | K23: =E23-I23-L23-M23-N23-J23+F23 -> 0 | N23: 2000 | O23: -500 | Q23: =Q22+N23+O23+P23 -> 11750
C24: 26-27 | D24: 1 | E24: 1900 | G24: 100 | K24: =E24-I24-L24-M24-N24-J24+F24 -> 0 | N24: 1900 | O24: -500 | Q24: =Q23+N24+O24+P24 -> 13150
C25: 27-29 | D25: 2 | E25: 3500 | I25: 1500 | K25: =E25-I25-L25-M25-N25-J25+F25 -> 0 | N25: 2000 | O25: -500 | Q25: =Q24+N25+O25+P25 -> 14650
C26: 29-30 | D26: 1 | E26: 2500 | I26: 1000 | K26: =E26-I26-L26-M26-N26-J26+F26 -> 0 | N26: 1500 | O26: -500 | Q26: =Q25+N26+O26+P26 -> 15650
C27: 30-31 | K27: =E27-I27-L27-M27-N27-J27+F27 -> 0 | Q27: =Q26+N27+O27+P27 -> 15650 | U27: 58080.36
C28: 31-1 | D28: 1 | E28: 1600 | I28: 500 | K28: =E28-I28-L28-M28-N28-J28+F28 -> 0 | N28: 1100 | O28: -500 | Q28: =Q27+N28+O28+P28 -> 16250 | U28: =U27-27368 -> 30712.36
P29: -2954.41 | Q29: =Q28+N29+O29+P29 -> 13295.59 | R29: Meralco
P30: -5472.35 | Q30: =Q29+N30+O30+P30 -> 7823.24 | R30: Association dues
K31: =E31-I31-L31-M31-N31-J31+F31 -> 0 | P31: -1627.64 | Q31: =Q30+N31+O31+P31 -> 6195.6 | R31: Airfryer
K32: =E32-I32-L32-M32-N32-J32+F32 -> 0 | P32: -2800 | Q32: =Q31+N32+O32+P32 -> 3395.6 | R32: Decor
P33: =-6195+2799 -> -3396 | Q33: =Q32+N33+O33+P33 -> -0.4 | R33: Remittance
B34: Jan | C34: Total | D34: =sum(D4:D31) -> 22 | E34: =sum(E4:E31) -> 46600 | G34: =sum(G4:G31) -> 950 | I34: =sum(I4:I31) -> 19200 | J34: =sum(J4:J31) -> 0 | K34: =sum(K4:K31) -> 0 | L34: =sum(L4:L31) -> 0 | M34: =sum(M4:M31) -> 2050 | N34: =sum(N4:N31) -> 26250 | O34: =sum(O4:O31) -> -10000 | P34: =sum(P4:P31) -> -10054.4 | Q34: =Q33 -> -0.4
B35: Feb | C35: 45659 | D35: 1 | E35: 2500 | J35: 1000 | K35: =E35-I35-L35-M35-N35-J35+F35 -> 0 | N35: 1500 | O35: -500 | Q35: =N35+O35+P35 -> 1000
C36: 45691 | D36: 1 | E36: 2500 | I36: 1000 | K36: =E36-I36-L36-M36-N36-J36+F36 -> 0 | N36: 1500 | O36: -500 | Q36: =Q35+N36+O36+P36 -> 2000
C37: 45720 | D37: 1 | E37: 2000 | I37: 1000 | K37: =E37-I37-L37-M37-N37-J37+F37 -> 0 | N37: 1000 | O37: -500 | Q37: =Q36+N37+O37+P37 -> 2500
C38: 45753 | K38: =E38-I38-L38-M38-N38-J38+F38 -> 0 | Q38: =Q37+N38+O38+P38 -> 2500
C39: 45815 | D39: 1 | E39: 2000 | I39: 1000 | K39: =E39-I39-L39-M39-N39-J39+F39 -> 0 | N39: 1000 | O39: -500 | Q39: =Q38+N39+O39+P39 -> 3000
C40: 45846 | D40: 1 | E40: 2300 | I40: 1000 | K40: =E40-I40-L40-M40-N40-J40+F40 -> 0 | N40: 1300 | O40: -500 | Q40: =Q39+N40+O40+P40 -> 3800
...

Sheet 1127
B1: 1127 BOOKING | L1: Payment | O1: 524 RECEIVABLE FROM ATE TESS
B2: Date | E2: Amount | F2: Parking | G2: Agent's Commission | H2: Remarks | I2: Reservation | K2: Balance | O2: Cleaning Fee | P2: Others | Q2: Receivable Balance | R2: Remarks
I3: BDO | J3: GCASH | L3: BDO | M3: GCASH | N3: Ate Tess
B4: DEC | C4: 45294 | K4: =E4-J4-L4-M4-N4-I4+F4 -> 0 | P4: 400 | Q4: =N4+O4+P4 -> 400 | R4: parking
C5: 45355 | D5: 1 | E5: 2000 | F5: 350 | J5: 1200 | K5: =E5-J5-L5-M5-N5-I5+F5 -> 0 | L5: 1150 | O5: -700 | Q5: =Q4+N5+O5+P5 -> -300
C6: 4-5 | D6: 1 | E6: 1707.2 | F6: 400 | H6: airbnb | K6: =E6-J6-L6-M6-N6-I6+F6-P6 -> 0 | L6: 1707.2 | O6: -700 | P6: 400 | Q6: =Q5+N6+O6+P6 -> -600 | R6: parking
C7: 45418 | D7: 1 | E7: 2600 | J7: 1000 | K7: =E7-J7-L7-M7-N7-I7+F7 -> 0 | N7: 1600 | O7: -700 | P7: 400 | Q7: =Q6+N7+O7+P7 -> 700 | R7: parking
C8: 6-7 | K8: =E8-J8-L8-M8-N8-I8+F8 -> 0 | Q8: =Q7+N8+O8+P8 -> 700
C9: 7-8 | D9: 1 | E9: 2700 | J9: 1000 | K9: =E9-J9-L9-M9-N9-I9+F9 -> 0 | M9: 1700 | O9: -700 | Q9: =Q8+N9+O9+P9 -> 0
C10: 45513 | D10: 1 | E10: 1707.2 | F10: 400 | H10: airbnb; p ate tess | K10: =E10-J10-L10-M10-N10-I10+F10-P10 -> 0 | L10: 1707.2 | O10: -700 | P10: 400 | Q10: =Q9+N10+O10+P10 -> -300
C11: 45545 | D11: 1 | E11: 2300 | F11: 400 | J11: 1000 | K11: =E11-J11-L11-M11-N11-I11+F11 -> 0 | M11: 1700 | O11: -700 | Q11: =Q10+N11+O11+P11 -> -1000
C12: 10-12 | D12: 2 | E12: 4100 | F12: 700 | I12: 1000 | J12: 500 | K12: =E12-J12-L12-M12-N12-I12+F12 -> 0 | L12: =2600+350 -> 2950 | N12: 350 | O12: -700 | Q12: =Q11+N12+O12+P12 -> -1350 | R12: parking
C13: 45639 | D13: 1 | E13: 2300 | J13: 2300 | K13: =E13-J13-L13-M13-N13-I13+F13 -> 0 | O13: -700 | P13: -150 | Q13: =Q12+N13+O13+P13 -> -2200
C14: 13-14 | D14: 1 | E14: 1637.51 | K14: =E14-J14-L14-M14-N14-I14+F14 -> 0 | L14: 1637.51 | O14: -700 | Q14: =Q13+N14+O14+P14 -> -2900
C15: 14-15 | D15: 1 | E15: 3200 | F15: 400 | J15: 1000 | K15: =E15-J15-L15-M15-N15-I15+F15 -> 0 | M15: 2600 | O15: -700 | Q15: =Q14+N15+O15+P15 -> -3600
C16: 15-16 | D16: 1 | E16: 2600 | F16: 400 | G16: -400 | J16: 1000 | K16: =E16-J16-L16-M16-N16-I16+F16 -> 0 | N16: 2000 | O16: -700 | Q16: =Q15+N16+O16+P16 -> -2300
C17: 16-17 | F17: 400 | K17: =E17-J17-L17-M17-N17-I17+F17 -> 0 | N17: 400 | Q17: =Q16+N17+O17+P17 -> -1900 | R17: parking
C18: 18-19 | D18: 1 | E18: 2300 | F18: 400 | J18: 1200 | K18: =E18-J18-L18-M18-N18-I18+F18 -> 0 | N18: 1500 | O18: -700 | Q18: =Q17+N18+O18+P18 -> -1100
C19: 19-20 | D19: 1 | E19: 2500 | G19: -400 | J19: 1000 | K19: =E19-J19-L19-M19-N19-I19+F19 -> 0 | N19: 1500 | O19: -700 | Q19: =Q18+N19+O19+P19 -> -300
C20: 20-21 | D20: 1 | E20: 2500 | J20: 500 | K20: =E20-J20-L20-M20-N20-I20+F20 -> 0 | N20: 2000 | O20: -700 | Q20: =Q19+N20+O20+P20 -> 1000
C21: 21-23 | D21: 2 | E21: =6700-450+50 -> 6300 | F21: =450 -> 450 | G21: -1000 | J21: =300+1600 -> 1900 | K21: =E21-J21-L21-M21-N21-I21+F21 -> 0 | N21: 4850 | O21: -700 | Q21: =Q20+N21+O21+P21 -> 5150
C22: 23-24 | D22: 1 | E22: 2500 | F22: 400 | J22: 1000 | K22: =E22-J22-L22-M22-N22-I22+F22-P22 -> 0 | N22: 1500 | O22: -700 | P22: 400 | Q22: =Q21+N22+O22+P22 -> 6350
C23: 24-26 | D23: 2 | E23: =4700*2 -> 9400 | F23: 1000 | J23: 2500 | K23: =E23-J23-L23-M23-N23-I23+F23 -> 0 | N23: 7900 | O23: -700 | P23: -1000 | Q23: =Q22+N23+O23+P23 -> 12550 | R23: violation
C24: 26-28 | D24: 2 | E24: 4500 | J24: 1500 | K24: =E24-J24-L24-M24-N24-I24+F24 -> 0 | N24: 3000 | O24: -700 | Q24: =Q23+N24+O24+P24 -> 14850
C25: 28-30 | D25: 2 | E25: 5700 | F25: 900 | J25: 1500 | K25: =E25-J25-L25-M25-N25-I25+F25 -> 0 | M25: 4200 | N25: 900 | O25: -700 | Q25: =Q24+N25+O25+P25 -> 15050
C26: 30-31 | K26: =E26-J26-L26-M26-N26-I26+F26 -> 0 | Q26: =Q25+N26+O26+P26 -> 15050
C27: 31-2 | D27: 2 | E27: 6700 | F27: 950 | J27: =2000+450 -> 2450 | K27: =E27-J27-L27-M27-N27-I27+F27 -> 0 | M27: 5200 | O27: -700 | P27: -5283.35 | Q27: =Q26+N27+O27+P27 -> 9066.65 | R27: Association dues
K28: =E28-J28-L28-M28-N28-I28+F28 -> 0 | P28: -4045 | Q28: =Q27+N28+O28+P28 -> 5021.65 | R28: Meralco | S28: 45662
P29: -50 | Q29: =Q28+N29+O29+P29 -> 4971.65 | R29: water
K30: =E30-J30-L30-M30-N30-I30+F30 -> 0 | P30: -500 | Q30: =Q29+N30+O30+P30 -> 4471.65 | R30: Grease trap
B31: DEC | C31: Total | D31: =sum(D4:D30) -> 26 | E31: =sum(E4:E30) -> 69251.91 | F31: =sum(F4:F30) -> 7550 | G31: =sum(G4:G30) -> -1800 | I31: =sum(I4:I30) -> 1000 | J31: =sum(J4:J30) -> 22550 | K31: =sum(K4:K30) -> 0 | L31: =sum(L4:L30) -> 9151.91 | M31: =sum(M4:M30) -> 15400 | N31: =sum(N4:N30) -> 27500 | O31: =sum(O4:O30) -> -14000 | P31: =sum(P4:P30) -> -9028.35 | Q31: =Q30 -> 4471.65
B32: JAN | C32: 45691 | D32: 1 | E32: 2300 | J32: 500 | K32: =E32-J32-L32-M32-N32-I32+F32 -> 0 | N32: 1800 | O32: -700 | Q32: =Q31+N32+O32+P32 -> 5571.65
C33: 45692 | E33: 1500 | H33: cancelled | J33: 1500 | K33: =E33-J33-L33-M33-N33-I33+F33 -> 0 | Q33: =Q32+N33+O33+P33 -> 5571.65 | R33: cancelled (2-4)
C34: 45720 | D34: 1 | E34: 2500 | J34: 1000 | K34: =E34-J34-L34-M34-N34-I34+F34 -> 0 | N34: 1500 | O34: -700 | Q34: =Q33+N34+O34+P34 -> 6371.65
C35: 45752 | D35: 1 | E35: 2800 | J35: 1000 | K35: =E35-J35-L35-M35-N35-I35+F35 -> 0 | N35: 1800 | O35: -700 | Q35: =Q34+N35+O35+P35 -> 7471.65
C36: 45785 | K36: =E36-J36-L36-M36-N36-I36+F36 -> 0 | Q36: =Q35+N36+O36+P36 -> 7471.65
C37: 45888 | D37: 11 | E37: 19000 | F37: =450+1950 -> 2400 | G37: -1000 | J37: =6000+2400 -> 8400 | K37: =E37-J37-L37-M37-N37-I37+F37-G37 -> 0 | N37: 14000 | O37: -700 | Q37: =Q36+N37+O37+P37 -> 20771.65
C38: 19-20 | K38: =E38-J38-L38-M38-N38-I38+F38 -> 0 | Q38: =Q37+N38+O38+P38 -> 20771.65
C39: 20-21 | D39: 1 | E39: 2000 | F39: 400 | J39: 500 | K39: =E39-J39-L39-M39-N39-I39+F39-P39 -> 0 | M39: 1500 | O39: -700 | P39: 400 | Q39: =Q38+N39+O39+P39 -> 20471.65 | R39: parking
C40: 21-22 | D40: 1 | E40: =1781.4 -> 1781.4 | F40: 400 | H40: airbnb | J40: 400 | K40: =E40-J40-L40-M40-N40-I40+F40-P40 -> 0 | L40: 1781.4 | O40: -700 | Q40: =Q39+N40+O40+P40 -> 19771.65
...

Sheet 1228
B1: 1228 BOOKING | L1: Full payment | P1: 1228 RECEIVABLE FROM ATE TESS
B2: Date | E2: Amount | F2: Parking | G2: Agent's Commissions | H2: Remarks | I2: Reservation | K2: Balance | O2: Cleaning Fee | P2: Others | Q2: Receivable Balance | R2: Remarks
I3: BDO | J3: Gcash | L3: BDO | M3: GCASH | N3: ATE TESS
B4: DEC | C4: 45293 | D4: 1 | E4: 1804.2 | H4: airbnb | K4: =E4-J4-L4-M4-N4-I4 -> 0 | L4: 1804.2 | O4: -700 | Q4: =N4+O4+P4 -> -700
C5: 45326 | K5: =E5-J5-L5-M5-N5-I5 -> 0 | Q5: =Q4+N5+O5+P5 -> -700
C6: 45387 | D6: 1 | E6: 2700 | J6: 1000 | K6: =E6-J6-L6-M6-N6-I6 -> 0 | N6: 1700 | O6: -700 | Q6: =Q5+N6+O6+P6 -> 300
C7: 45418 | D7: 1 | E7: 1788.68 | H7: Airbnb | K7: =E8-J8-L8-M8-N8-I8 -> 0 | L7: 1788.68 | O7: -700 | Q7: =Q6+N7+O7+P7 -> -400
C8: 45450 | D8: 1 | E8: 2000 | J8: 500 | K8: =E8-J8-L8-M8-N8-I8 -> 0 | M8: 1500 | O8: -700 | Q8: =Q7+N8+O8+P8 -> -1100
C9: 7-8 | D9: 1 | E9: 3000 | J9: 1000 | K9: =E9-J9-L9-M9-N9-I9 -> 0 | N9: 2000 | O9: -700 | Q9: =Q8+N9+O9+P9 -> 200
C10: 45513 | D10: 1 | E10: 2800 | J10: 1000 | K10: =E10-J10-L10-M10-N10-I10 -> 0 | L10: 1800 | O10: -700 | Q10: =Q9+N10+O10+P10 -> -500
C11: 45546 | D11: 2 | E11: 4300 | J11: 1500 | K11: =E11-J11-L11-M11-N11-I11 -> 0 | M11: 2800 | O11: -700 | Q11: =Q10+N11+O11+P11 -> -1200
C12: 45610 | K12: =E12-J12-L12-M12-N12-I12 -> 0 | Q12: =Q11+N12+O12+P12 -> -1200
C13: 14-15 | D13: 1 | E13: 2700 | J13: 1000 | K13: =E13-J13-L13-M13-N13-I13 -> 0 | N13: 1700 | O13: -700 | Q13: =Q12+N13+O13+P13 -> -200
C14: 15-18 | Q14: =Q13+N14+O14+P14 -> -200
C15: 18-19 | D15: 1 | E15: 2500 | J15: 1000 | K15: =E15-J15-L15-M15-N15-I15 -> 0 | M15: 1500 | O15: -700 | Q15: =Q14+N15+O15+P15 -> -900
C16: 19-20 | D16: 1 | E16: 2500 | J16: 1000 | K16: =E16-J16-L16-M16-N16-I16 -> 0 | N16: 1500 | O16: -700 | Q16: =Q15+N16+O16+P16 -> -100
C17: 20-21 | D17: 1 | E17: 2300 | J17: 1000 | K17: =E17-J17-L17-M17-N17-I17 -> 0 | N17: 1300 | O17: -700 | Q17: =Q16+N17+O17+P17 -> 500
C18: 21-22 | D18: 1 | E18: 3200 | J18: 1000 | K18: =E18-J18-L18-M18-N18-I18 -> 0 | N18: 2200 | O18: -700 | Q18: =Q17+N18+O18+P18 -> 2000
C19: 22-23 | D19: 1 | E19: 2300 | J19: 500 | K19: =E19-J19-L19-M19-N19-I19 -> 0 | N19: 1800 | O19: -700 | Q19: =Q18+N19+O19+P19 -> 3100
C20: 23-24 | D20: 1 | E20: 2500 | J20: 1000 | K20: =E20-J20-L20-M20-N20-I20 -> 0 | N20: 1500 | O20: -700 | Q20: =Q19+N20+O20+P20 -> 3900
C21: 24-26 | D21: 2 | E21: 7700 | J21: 1500 | K21: =E21-J21-L21-M21-N21-I21 -> 0 | M21: 1300 | N21: 4900 | O21: -700 | P21: -1000 | Q21: =Q20+N21+O21+P21 -> 7100
C22: 26-27 | D22: 1 | E22: 2100 | J22: 1000 | K22: =E22-J22-L22-M22-N22-I22 -> 0 | N22: 1100 | O22: -700 | Q22: =Q21+N22+O22+P22 -> 7500
C23: 27-28 | D23: 1 | E23: 3000 | J23: 1000 | K23: =E23-J23-L23-M23-N23-I23 -> 0 | N23: 2000 | O23: -700 | Q23: =Q22+N23+O23+P23 -> 8800
C24: 28-29 | D24: 1 | E24: 3000 | J24: 1000 | K24: =E24-J24-L24-M24-N24-I24 -> 0 | N24: 2000 | O24: -700 | Q24: =Q23+N24+O24+P24 -> 10100
C25: 29-30 | D25: 1 | E25: 3700 | J25: 1000 | K25: =E25-J25-L25-M25-N25-I25 -> 0 | N25: 2700 | O25: -700 | Q25: =Q24+N25+O25+P25 -> 12100
C26: 30-1 | D26: 2 | E26: 5700 | J26: 1500 | K26: =E26-J26-L26-M26-N26-I26 -> 0 | L26: 4200 | O26: -700 | Q26: =Q25+N26+O26+P26 -> 11400
K27: =E27-J27-L27-M27-N27-I27 -> 0 | P27: -500 | Q27: =Q26+N27+O27+P27 -> 10900 | R27: grease trap
K28: =E28-J28-L28-M28-N28-I28 -> 0 | P28: -5081.29 | Q28: =Q27+N28+O28+P28 -> 5818.71 | R28: Association Dues
B29: DEC | C29: TOTAL | D29: =SUM(D4:D28) -> 23 | E29: =SUM(E4:E28) -> 61592.88 | G29: =SUM(G4:G28) -> 0 | H29: =SUM(H4:H28) -> 0 | I29: =SUM(I4:I28) -> 0 | J29: =SUM(J4:J28) -> 18500 | K29: =SUM(K4:K28) -> 0 | L29: =SUM(L4:L28) -> 9592.88 | M29: =SUM(M4:M28) -> 7100 | N29: =SUM(N4:N28) -> 26400 | ... P29: =SUM(P4:P28) -> -6581.29 | Q29: =Q28 -> 5818.71
B30: Jan | C30: 45659 | D30: 1 | E30: 2800 | J30: 1000 | K30: =E30-J30-L30-M30-N30-I30 -> 0 | N30: 1800 | O30: -700 | Q30: =Q29+N30+O30+P30 -> 6918.71
C31: 45691 | D31: 1 | E31: 2300 | J31: 1000 | K31: =E31-J31-L31-M31-N31-I31 -> 0 | N31: 1300 | O31: -700 | Q31: =Q30+N31+O31+P31 -> 7518.71
C32: 3-4 | D32: 1 | E32: 2750 | J32: 1000 | K32: =E32-J32-L32-M32-N32-I32 -> 0 | L32: 1750 | O32: -700 | Q32: =Q31+N32+O32+P32 -> 6818.71
C33: 45752 | D33: 1 | E33: 2800 | J33: 1000 | K33: =E33-J33-L33-M33-N33-I33 -> 0 | N33: 1800 | O33: -700 | Q33: =Q32+N33+O33+P33 -> 7918.71
C34: 5-6 | D34: 1 | E34: 2200 | G34: 400 | J34: 1000 | K34: =E34-J34-L34-M34-N34-I34 -> 0 | N34: 1200 | O34: -700 | Q34: =Q33+N34+O34+P34 -> 8418.71
C35: 45815 | D35: 1 | E35: 2300 | J35: 500 | K35: =E35-J35-L35-M35-N35-I35 -> 0 | N35: 1800 | O35: -700 | Q35: =Q34+N35+O35+P35 -> 9518.71
C36: 45848 | K36: =E36-J36-L36-M36-N36-I36 -> 0 | Q36: =Q35+N36+O36+P36 -> 9518.71
C37: 45942 | D37: 2 | E37: 5300 | J37: 1500 | K37: =E37-J37-L37-M37-N37-I37 -> 0 | M37: 3800 | O37: -700 | Q37: =Q36+N37+O37+P37 -> 8818.71
C38: 46004 | D38: 1 | E38: =2800+400 -> 3200 | J38: 1000 | K38: =E38-J38-L38-M38-N38-I38 -> 0 | M38: 2200 | O38: -700 | Q38: =Q37+N38+O38+P38 -> 8118.71
C39: 14-15 | K39: =E39-J39-L39-M39-N39-I39 -> 0 | Q39: =Q38+N39+O39+P39 -> 8118.71
C40: 15-16 | D40: 1 | E40: 2300 | J40: 1000 | K40: =E40-J40-L40-M40-N40-I40 -> 0 | N40: 1300 | O40: -700 | Q40: =Q39+N40+O40+P40 -> 8718.71
...

Sheet 1230
B1: 1230 BOOKING | L1: Payment | O1: 1230 RECEIVABLE FROM ATE TESS
B2: Date | E2: Amount | F2: Parking | G2: Agent's Commission | H2: Remarks | I2: Reservation | K2: Balance | O2: Cleaning Fee | P2: Others | Q2: Receivable Balance | R2: Remarks
I3: BDO | J3: Gcash | L3: BDO | M3: GCASH | N3: Ate Tess
B4: DEC | C4: 45293 | D4: 1 | E4: 1804.2 | F4: 400 | K4: =E4-J4-L4-M4-N4-I4+F4 -> 0 | L4: 1804.2 | N4: 400 | O4: -700 | Q4: =N4+O4+P4 -> -300
C5: 45325 | K5: =E5-J5-L5-M5-N5-I5+F5 -> 0 | Q5: =Q4+N5+O5+P5 -> -300
C6: 3-4 | D6: 1 | E6: 2260.1 | H6: airbnb | K6: =E6-J6-L6-M6-N6-I6+F6 -> 0 | L6: 2260.1 | O6: -700 | Q6: =Q5+N6+O6+P6 -> -1000
C7: 4-6 | D7: 2 | E7: 4100 | J7: 1000 | K7: =E7-J7-L7-M7-N7-I7+F7 -> 0 | N7: 3100 | O7: -700 | Q7: =Q6+N7+O7+P7 -> 1400
C8: 45450 | D8: 1 | E8: 2500 | J8: 1000 | K8: =E8-J8-L8-M8-N8-I8+F8 -> 0 | N8: 1500 | O8: -700 | Q8: =Q7+N8+O8+P8 -> 2200
C9: 45482 | E9: 1500 | H9: cancelled | J9: 1500 | K9: =E9-J9-L9-M9-N9-I9+F9 -> 0 | Q9: =Q8+N9+O9+P9 -> 2200
C10: 45481 | D10: 1 | E10: 2800 | K10: =E10-J10-L10-M10-N10-I10+F10 -> 0 | N10: 2800 | O10: -700 | Q10: =Q9+N10+O10+P10 -> 4300
C11: 45513 | D11: 1 | E11: 2500 | H11: 400 to ate tess | K11: =E11-J11-L11-M11-N11-I11+F11 -> 0 | N11: 2500 | O11: -700 | P11: -400 | Q11: =Q10+N11+O11+P11 -> 5700 | R11: parking ate tess
C12: 9-10 | D12: 1 | E12: =2300+200 -> 2500 | J12: 1000 | K12: =E12-J12-L12-M12-N12-I12+F12 -> 0 | M12: 200 | N12: 1300 | O12: -700 | Q12: =Q11+N12+O12+P12 -> 6300
C13: 10-11 | K13: =E13-J13-L13-M13-N13-I13+F13 -> 0 | Q13: =Q12+N13+O13+P13 -> 6300
C14: 11-13 | D14: 2 | E14: 4100 | I14: 1500 | K14: =E14-J14-L14-M14-N14-I14+F14 -> 0 | N14: 2600 | O14: -700 | Q14: =Q13+N14+O14+P14 -> 8200
C15: 13-14 | E15: 500 | H15: cancelled | K15: =E15-J15-L15-M15-N15-I15+F15 -> 0 | M15: 500 | Q15: =Q14+N15+O15+P15 -> 8200
C16: 14-15 | D16: 1 | E16: 3000 | J16: 1000 | K16: =E16-J16-L16-M16-N16-I16+F16 -> 0 | N16: 2000 | O16: -700 | Q16: =Q15+N16+O16+P16 -> 9500
C17: 15-16 | D17: 1 | E17: 2800 | J17: 1000 | K17: =E17-J17-L17-M17-N17-I17+F17 -> 0 | N17: 1800 | O17: -700 | Q17: =Q16+N17+O17+P17 -> 10600
C18: 16-18 | D18: 2 | E18: 3500 | J18: 1500 | K18: =E18-J18-L18-M18-N18-I18+F18 -> 0 | M18: 2000 | O18: -700 | Q18: =Q17+N18+O18+P18 -> 9900
C19: 18-19 | D19: 1 | E19: 1993.83 | K19: =E19-J19-L19-M19-N19-I19+F19 -> 0 | L19: 1993.83 | O19: -700 | Q19: =Q18+N19+O19+P19 -> 9200
C20: 19-20 | D20: 1 | E20: 2300 | F20: 350 | J20: 1000 | K20: =E20-J20-L20-M20-N20-I20+F20-P20 -> 0 | N20: 1300 | O20: -700 | P20: 350 | Q20: =Q19+N20+O20+P20 -> 10150 | R20: parking
C21: 20-22 | D21: 2 | E21: 5500 | F21: 900 | J21: 1950 | K21: =E21-J21-L21-M21-N21-I21+F21 -> 0 | N21: 4450 | O21: -700 | Q21: =Q20+N21+O21+P21 -> 13900
C22: 22-24 | D22: 2 | E22: =4100+500 -> 4600 | G22: -500 | H22: iris | J22: 1500 | K22: =E22-J22-L22-M22-N22-I22+F22 -> 0 | N22: 3100 | O22: -700 | Q22: =Q21+N22+O22+P22 -> 16300
C23: 24-26 | D23: 2 | E23: 6200 | J23: 1500 | K23: =E23-J23-L23-M23-N23-I23+F23 -> 0 | N23: 4700 | O23: -700 | Q23: =Q22+N23+O23+P23 -> 20300
C24: 26-28 | D24: 2 | E24: =2500*2 -> 5000 | H24: ma'am naicy | K24: =E24-J24-L24-M24-N24-I24+F24 -> 0 | L24: 5000 | O24: -700 | Q24: =Q23+N24+O24+P24 -> 19600
C25: 28-30 | D25: 2 | E25: 6500 | I25: 1500 | K25: =E25-J25-L25-M25-N25-I25+F25 -> 0 | N25: 5000 | O25: -700 | Q25: =Q24+N25+O25+P25 -> 23900
C26: 30-31 | D26: 1 | E26: 3000 | F26: 400 | J26: 1400 | K26: =E26-J26-L26-M26-N26-I26+F26 -> 0 | N26: 2000 | O26: -700 | Q26: =Q25+N26+O26+P26 -> 25200
C27: 31-2 | D27: 2 | E27: 7000 | J27: 2000 | K27: =E27-J27-L27-M27-N27-I27+F27 -> 0 | N27: 5000 | O27: -700 | Q27: =Q26+N27+O27+P27 -> 29500
K28: =E28-J28-L28-M28-N28-I28+F28 -> 0 | P28: -500 | Q28: =Q27+N28+O28+P28 -> 29000 | R28: grease trap
K29: =E29-J29-L29-M29-N29-I29+F29 -> 0 | P29: -5476.23 | Q29: =Q28+N29+O29+P29 -> 23523.77 | R29: Association dues
K30: =E30-J30-L30-M30-N30-I30+F30 -> 0 | P30: -2516.41 | Q30: =Q29+N30+O30+P30 -> 21007.36 | R30: Meralco
B31: DEC | C31: TOTAL | D31: =SUM(D4:D30) -> 29 | E31: =SUM(E4:E30) -> 75958.13 | F31: =SUM(F4:F30) -> 2050 | G31: =SUM(G4:G30) -> -500 | H31: =SUM(H4:H30) -> 0 | I31: =SUM(I4:I30) -> 3000 | J31: =SUM(J4:J30) -> 17350 | K31: =SUM(K4:K30) -> 0 | ... P31: =SUM(P4:P30) -> -8542.64 | Q31: =Q30 -> 21007.36
B32: JAN | C32: 45325 | D32: 1 | E32: 2300 | J32: 1000 | K32: =E32-J32-L32-M32-N32-I32+F32 -> 0 | N32: 1300 | O32: -700 | Q32: =Q31+N32+O32+P32 -> 21607.36
C33: 45720 | D33: 1 | E33: 2300 | F33: 450 | J33: 1000 | K33: =E33-J33-L33-M33-N33-I33+F33 -> 0 | N33: 1750 | O33: -700 | Q33: =Q32+N33+O33+P33 -> 22657.36
C34: 45752 | D34: 1 | E34: 2700 | J34: 1000 | K34: =E34-J34-L34-M34-N34-I34+F34 -> 0 | N34: 1700 | O34: -700 | Q34: =Q33+N34+O34+P34 -> 23657.36
C35: 45784 | D35: 2 | E35: 4000 | J35: 500 | K35: =E35-J35-L35-M35-N35-I35+F35 -> 0 | N35: 3500 | O35: -700 | Q35: =Q34+N35+O35+P35 -> 26457.36
C36: 45847 | D36: 2 | E36: 4617.2 | K36: =E36-J36-L36-M36-N36-I36+F36 -> 0 | L36: 4617.2 | O36: -700 | Q36: =Q35+N36+O36+P36 -> 25757.36
C37: 45910 | K37: =E37-J37-L37-M37-N37-I37+F37 -> 0 | Q37: =Q36+N37+O37+P37 -> 25757.36
C38: 45941 | D38: 1 | E38: 2500 | J38: 1000 | K38: =E38-J38-L38-M38-N38-I38+F38 -> 0 | N38: 1500 | O38: -700 | Q38: =Q37+N38+O38+P38 -> 26557.36
C39: 45973 | D39: 1 | E39: 3050 | J39: 1000 | K39: =E39-J39-L39-M39-N39-I39+F39 -> 0 | N39: 2050 | O39: -700 | Q39: =Q38+N39+O39+P39 -> 27907.36
C40: 46004 | D40: 1 | E40: 2575.84 | K40: =E40-J40-L40-M40-N40-I40+F40 -> 0 | L40: 2575.84 | O40: -700 | Q40: =Q39+N40+O40+P40 -> 27207.36
...

Sheet 828
B1: 828 BOOKING | L1: Payment | O1: 828 RECEIVABLE FROM ATE TESS
B2: Date | E2: Amount | F2: Agent's Commission | G2: Parking | H2: Remarks | I2: Reservation | K2: Balance | O2: Cleaning Fee | P2: Others | Q2: Receivable Balance | R2: Remarks
I3: BDO | J3: GCASH | L3: BDO | M3: GCASH | N3: Ate Tess
B4: DEC | C4: 45293 | D4: 1 | E4: 2300 | F4: -500 | H4: Con | J4: 500 | K4: =E4-J4-L4-M4-N4-I4+G4 -> 0 | N4: 1800 | O4: -700 | Q4: =N4+O4+P4 -> 1100 | T4: 828 | U4: =Q28 -> 14679.06
C5: 45326 | K5: =E5-J5-L5-M5-N5-I5+G5 -> 0 | Q5: =Q4+N5+O5+P5 -> 1100
C6: 4-9 | D6: 5 | E6: 9000 | G6: =800+900 -> 1700 | H6: Parking (5-7) | J6: 3000 | K6: =E6-J6-L6-M6-N6-I6+G6 -> 0 | M6: 7700 | O6: -700 | Q6: =Q5+N6+O6+P6 -> 400
C7: 45545 | D7: 1 | E7: 2100 | J7: 1000 | K7: =E7-J7-L7-M7-N7-I7+G7 -> 0 | N7: 1100 | O7: -700 | Q7: =Q6+N7+O7+P7 -> 800
C8: 45578 | E8: 500 | H8: cancelled | J8: 500 | K8: =E8-J8-L8-M8-N8-I8+G8 -> 0 | Q8: =Q7+N8+O8+P8 -> 800
C9: 13-14 | D9: 1 | E9: 2000 | K9: =E9-J9-L9-M9-N9-I9+G9 -> 0 | N9: 2000 | O9: -700 | Q9: =Q8+N9+O9+P9 -> 2100
C10: 14-16 | D10: 2 | E10: 5300 | J10: 1500 | K10: =E10-J10-L10-M10-N10-I10+G10 -> 0 | N10: 3800 | O10: -700 | Q10: =Q9+N10+O10+P10 -> 5200
C11: 16-18 | Q11: =Q10+N11+O11+P11 -> 5200
C12: 18-19 | D12: 1 | E12: 1800 | J12: 800 | K12: =E12-J12-L12-M12-N12-I12+G12 -> 0 | N12: 1000 | O12: -700 | Q12: =Q11+N12+O12+P12 -> 5500
C13: 19-20 | D13: 1 | E13: 2300 | G13: 300 | J13: 1500 | K13: =E13-J13-L13-M13-N13-I13+G13-P13 -> 0 | N13: 800 | O13: -700 | P13: 300 | Q13: =Q12+N13+O13+P13 -> 5900 | R13: Parking
C14: 20-21 | D14: 1 | E14: 2500 | J14: 1000 | K14: =E14-J14-L14-M14-N14-I14+G14 -> 0 | N14: 1500 | O14: -700 | Q14: =Q13+N14+O14+P14 -> 6700
C15: 21-22 | D15: 1 | E15: 4500 | F15: -700 | H15: con | I15: 1000 | K15: =E15-J15-L15-M15-N15-I15+G15 -> 0 | N15: 3500 | O15: -700 | P15: -500 | Q15: =Q14+N15+O15+P15 -> 9000 | R15: violation
C16: 22-23 | D16: 1 | E16: 2300 | J16: 1000 | K16: =E16-J16-L16-M16-N16-I16+G16 -> 0 | N16: 1300 | O16: -700 | Q16: =Q15+N16+O16+P16 -> 9600
C17: 23-26 | D17: 3 | E17: 9500 | J17: 2000 | K17: =E17-J17-L17-M17-N17-I17+G17 -> 0 | N17: 7500 | O17: -700 | Q17: =Q16+N17+O17+P17 -> 16400
C18: 26-28 | D18: 2 | E18: 4500 | J18: 1500 | K18: =E18-J18-L18-M18-N18-I18+G18 -> 0 | N18: 3000 | O18: -700 | Q18: =Q17+N18+O18+P18 -> 18700
C19: 28-30 | E19: 1500 | H19: cancelled | J19: 1500 | K19: =E19-J19-L19-M19-N19-I19+G19 -> 0 | Q19: =Q18+N19+O19+P19 -> 18700 | R19: cancelled
C20: 28-29 | D20: 1 | E20: 2500 | J20: 500 | K20: =E20-J20-L20-M20-N20-I20+G20 -> 0 | M20: 2000 | O20: -700 | Q20: =Q19+N20+O20+P20 -> 18000
C21: 29-30 | D21: 1 | E21: 2000 | J21: 500 | K21: =E21-J21-L21-M21-N21-I21+G21 -> 0 | N21: 1500 | O21: -700 | Q21: =Q20+N21+O21+P21 -> 18800
C22: 30-1 | E22: 1500 | H22: cancelled | J22: 1500 | K22: =E22-J22-L22-M22-N22-I22+G22 -> 0 | Q22: =Q21+N22+O22+P22 -> 18800 | R22: cancelled
C23: 31-1 | D23: 1 | E23: 2500 | J23: 1000 | K23: =E23-J23-L23-M23-N23-I23+G23 -> 0 | N23: 1500 | O23: -700 | Q23: =Q22+N23+O23+P23 -> 19600
K24: =E24-J24-L24-M24-N24-I24+G24 -> 0 | P24: -1145 | Q24: =Q23+N24+O24+P24 -> 18455 | R24: Water
K25: =E25-J25-L25-M25-N25-I25+G25 -> 0 | P25: -895.29 | Q25: =Q24+N25+O25+P25 -> 17559.71 | R25: Excss
K26: =E26-J26-L26-M26-N26-I26+G26 -> 0 | P26: -500 | Q26: =Q25+N26+O26+P26 -> 17059.71 | R26: Grease trap
K27: =E27-J27-L27-M27-N27-I27+G27 -> 0 | P27: -2380.65 | Q27: =Q26+N27+O27+P27 -> 14679.06 | R27: Meralco
B28: DEC | C28: TOTAL | D28: =sum(D4:D27) -> 23 | E28: =sum(E4:E27) -> 58600 | F28: =sum(F4:F27) -> -1200 | G28: =sum(G4:G27) -> 2000 | H28: =sum(H4:H27) -> 0 | I28: =sum(I4:I27) -> 1000 | J28: =sum(J4:J27) -> 19300 | K28: =sum(K4:K27) -> 0 | ... P28: =sum(P4:P27) -> -5120.94 | Q28: =Q27 -> 14679.06
B29: JAN | C29: 45660 | K29: =E29-J29-L29-M29-N29-I29+G29 -> 0 | Q29: =Q28+N29+O29+P29 -> 14679.06
C30: 45720 | D30: 1 | E30: 2500 | J30: 1000 | K30: =E30-J30-L30-M30-N30-I30+G30 -> 0 | M30: 1500 | O30: -700 | Q30: =Q29+N30+O30+P30 -> 13979.06
C31: 45753 | D31: 1 | E31: 2000 | K31: =E31-J31-L31-M31-N31-I31+G31 -> 0 | N31: 2000 | O31: -700 | Q31: =Q30+N31+O31+P31 -> 15279.06
C32: 45783 | K32: =E32-J32-L32-M32-N32-I32+G32 -> 0 | Q32: =Q30+N32+O32+P32 -> 13979.06
C33: 45815 | D33: 1 | E33: 2000 | J33: 1000 | K33: =E33-J33-L33-M33-N33-I33+G33 -> 0 | M33: 1000 | O33: -700 | Q33: =Q32+N33+O33+P33 -> 13279.06
C34: 45848 | K34: =E34-J34-L34-M34-N34-I34+G34 -> 0 | Q34: =Q33+N34+O34+P34 -> 13279.06
C35: 45941 | D35: 1 | E35: 2300 | J35: 500 | K35: =E35-J35-L35-M35-N35-I35+G35 -> 0 | N35: 1800 | O35: -700 | Q35: =Q34+N35+O35+P35 -> 14379.06
C36: 45973 | D36: 1 | E36: 2500 | I36: 1000 | K36: =E36-J36-L36-M36-N36-I36+G36 -> 0 | N36: 1500 | O36: -700 | Q36: =Q35+N36+O36+P36 -> 15179.06
C37: 46006 | K37: =E37-J37-L37-M37-N37-I37+G37 -> 0 | Q37: =Q36+N37+O37+P37 -> 15179.06
C38: 15-16 | D38: 1 | E38: 2300 | F38: -500 | H38: con | J38: 1000 | K38: =E38-J38-L38-M38-N38-I38+G38 -> 0 | N38: 1300 | O38: -700 | Q38: =Q37+N38+O38+P38 -> 15779.06
C39: 16-17 | K39: =E39-J39-L39-M39-N39-I39+G39 -> 0 | Q39: =Q38+N39+O39+P39 -> 15779.06
C40: 17-18 | D40: 1 | E40: 2500 | J40: 500 | K40: =E40-J40-L40-M40-N40-I40+G40 -> 0 | M40: 2000 | O40: -700 | Q40: =Q39+N40+O40+P40 -> 15079.06
...

Sheet 105
B1: 105 BOOKING | L1: Full payment | P1: 105 RECEIVABLE FROM ATE CZARINA
B2: Date | E2: Amount | F2: Parking | G2: Agent's Commissions | H2: Remarks | I2: Reservation | K2: Balance | O2: Cleaning Fee | P2: Others | Q2: Receivable Balance | R2: Remarks
I3: Gcash | J3: BDO | L3: BDO | M3: GCASH | N3: Ate CZARINA
B4: Feb | C4: 13-14 | D4: 1 | E4: 1500 | I4: 500 | K4: =E4-I4-L4-M4-N4-J4+F4 -> 0 | M4: 1000 | O4: -500 | Q4: =Q3+N4+O4+P4 -> -500
C5: 14-15 | D5: 1 | E5: 2200 | J5: 1000 | K5: =E5-I5-L5-M5-N5-J5+F5 -> 0 | N5: 1200 | O5: -500 | Q5: =Q4+N5+O5+P5 -> 200
C6: 15-16 | D6: 1 | E6: 2000 | I6: 700 | K6: =E6-I6-L6-M6-N6-J6+F6 -> 1 | N6: 1299 | O6: -500 | Q6: =Q5+N6+O6+P6 -> 999
C7: 16-17 | D7: 1 | E7: 2000 | I7: 1000 | K7: =E7-I7-L7-M7-N7-J7+F7 -> 0 | N7: 1000 | O7: -500 | Q7: =Q6+N7+O7+P7 -> 1499
C8: 17-18 | K8: =E8-I8-L8-M8-N8-J8+F8 -> 0 | Q8: =Q7+N8+O8+P8 -> 1499
C9: 18-20 | D9: 2 | E9: 3300 | I9: 1500 | K9: =E9-I9-L9-M9-N9-J9+F9 -> 0 | M9: 1800 | O9: -500 | Q9: =Q8+N9+O9+P9 -> 999
C10: 20-21 | K10: =E10-I10-L10-M10-N10-J10+F10 -> 0 | Q10: =Q9+N10+O10+P10 -> 999
C11: 21-22 | D11: 1 | E11: 2000 | I11: 1000 | K11: =E11-I11-L11-M11-N11-J11+F11 -> 0 | N11: 1000 | O11: -500 | Q11: =Q10+N11+O11+P11 -> 1499
C12: 22-23 | D12: 1 | E12: 2500 | G12: -200 | I12: 500 | K12: =E12-I12-L12-M12-N12-J12+F12 -> 0 | M12: 2000 | O12: -500 | Q12: =Q11+N12+O12+P12 -> 999
C13: 23-25 | D13: 2 | E13: 3300 | K13: =E13-I13-L13-M13-N13-J13+F13 -> 0 | M13: 3300 | O13: -500 | Q13: =Q12+N13+O13+P13 -> 499
K14: =E14-I14-L14-M14-N14-J14+F14 -> 0 | Q14: =Q13+N14+O14+P14 -> 499
K15: =E15-I15-L15-M15-N15-J15+F15 -> 0 | Q15: =Q14+N15+O15+P15 -> 499
C16: 28-2 | D16: 2 | E16: 3317.4 | G16: =50+400 -> 450 | H16: airbnb | K16: =E16-I16-L16-M16-N16-J16+F16 -> 0 | L16: 3317.4 | O16: -500 | Q16: =Q15+N16+O16+P16 -> -1
P17: -500 | Q17: =Q16+N17+O17+P17 -> -501 | R17: Cleaning
P18: -500 | Q18: =Q17+N18+O18+P18 -> -1001 | R18: Laundry
P19: 1001 | Q19: =Q18+N19+O19+P19 -> 0
B20: Feb | C20: Total | D20: =sum(D4:D18) -> 12 | E20: =sum(E4:E18) -> 22117.4 | G20: =sum(G4:G18) -> 250 | I20: =sum(I4:I18) -> 5200 | J20: =sum(J4:J18) -> 1000 | K20: =sum(K4:K18) -> 1 | L20: =sum(L4:L18) -> 3317.4 | M20: =sum(M4:M18) -> 8100 | N20: =sum(N4:N18) -> 4499 | O20: =sum(O4:O18) -> -4500 | P20: =sum(P4:P19) -> 1 | Q20: =Q19 -> 0
B21: Mar | C21: 45691 | D21: 1 | E21: 2000 | I21: 1000 | K21: =E21-I21-L21-M21-N21-J21+F21 -> 0 | N21: 1000 | O21: -500 | Q21: =Q20+N21+O21+P21 -> 500
C22: 45720 | K22: =E22-I22-L22-M22-N22-J22+F22 -> 0 | Q22: =Q21+N22+O22+P22 -> 500
C23: 45752 | D23: 1 | E23: 1999 | I23: 500 | K23: =E23-I23-L23-M23-N23-J23+F23 -> 0 | N23: 1499 | O23: -500 | Q23: =Q22+N23+O23+P23 -> 1499
C24: 45783 | D24: 1 | E24: 1600 | I24: 500 | K24: =E24-I24-L24-M24-N24-J24+F24 -> 0 | N24: 1100 | O24: -500 | Q24: =Q23+N24+O24+P24 -> 2099
C25: 45815 | K25: =E25-I25-L25-M25-N25-J25+F25 -> 0 | Q25: =Q24+N25+O25+P25 -> 2099
C26: 45847 | D26: 2 | E26: 3900 | I26: 1500 | K26: =E26-I26-L26-M26-N26-J26+F26 -> 0 | N26: 2400 | O26: -500 | Q26: =Q25+N26+O26+P26 -> 3999
C27: 45916 | D27: 7 | E27: 11900 | I27: 4000 | K27: =E27-I27-L27-M27-N27-J27+F27 -> 0 | N27: 7900 | O27: -500 | Q27: =Q26+N27+O27+P27 -> 11399
C28: 16-22 | Q28: =Q27+N28+O28+P28 -> 11399
C29: 22-24 | D29: 2 | E29: 3084.6 | K29: =E29-I29-L29-M29-N29-J29+F29 -> 0 | L29: 3084.6 | O29: -500 | Q29: =Q28+N29+O29+P29 -> 10899
C30: 24-25 | D30: 1 | E30: 1800 | K30: =E30-I30-L30-M30-N30-J30+F30 -> 0 | N30: 1800 | O30: -500 | Q30: =Q29+N30+O30+P30 -> 12199
C31: 25-26 | D31: 1 | E31: 1800 | I31: 1000 | K31: =E31-I31-L31-M31-N31-J31+F31 -> 0 | N31: 800 | O31: -500 | Q31: =Q30+N31+O31+P31 -> 12499
C32: 26-28 | K32: =E32-I32-L32-M32-N32-J32+F32 -> 0 | Q32: =Q31+N32+O32+P32 -> 12499
C33: 28-29 | D33: 1 | E33: 2100 | F33: 350 | I33: 1200 | K33: =E33-I33-L33-M33-N33-J33+F33 -> 0 | N33: 1250 | O33: -500 | Q33: =Q32+N33+O33+P33 -> 13249
C34: 29-31 | D34: 2 | E34: 4100 | I34: 1500 | K34: =E34-I34-L34-M34-N34-J34+F34 -> 0 | N34: 2600 | O34: -500 | Q34: =Q33+N34+O34+P34 -> 15349
C35: 31-2 | D35: 2 | E35: 3900 | I35: 1500 | N35: 2400 | O35: -500 | Q35: =Q34+N35+O35+P35 -> 17249
P36: -849 | Q36: =Q35+N36+O36+P36 -> 16400 | R36: Bidet
K37: =E37-I37-L37-M37-N37-J37+F37 -> 0 | P37: -909.4 | Q37: =Q36+N37+O37+P37 -> 15490.6 | R37: water
P38: -3163.61 | Q38: =Q37+N38+O38+P38 -> 12326.99 | R38: meralco | T38: 909.4
P39: -500 | Q39: =Q38+N39+O39+P39 -> 11826.99 | R39: grease trap
P40: -150 | Q40: =Q39+N40+O40+P40 -> 11676.99 | R40: Bidet replace
...

Sheet Summary
B2: Ate Tess Summary | G2: Ate Czarina Summary
B3: December- February Balance | G3: February
C4: 1228 | D4: 278.03 | H4: 105 | J4: -1001
C5: 1127 | D5: 23000.15 | H5: 635 | J5: 12404.5
C6: 1230 | D6: 39131.11 | H6: 1931 | J6: 12230.94
C7: 828 | D7: 19368.41 | H7: Total | J7: =J4+J6+J5 -> 23634.44
B8: Total | D8: =D4+D5+D6+D7 -> 81777.7 | H8: Foam | J8: -1999
B9: January Deposit | D9: 60000 | H9: battery | J9: -159
B10: Balance | D10: =D8-D9 -> 21777.7 | H10: 1231 internet | J10: 850
B11: assoc dues 828 | D11: -9610.18 | H11: Balance | J11: =sum(J7:J10) -> 22326.44
B12: Water Heater | D12: -5550
B13: February | D13: =D10+D11+D12 -> 6617.52 | G13: March | H13: 105 | J13: 16400
H14: 635 | J14: 19799
H15: 1931 | J15: 15249
H16: Total | J16: =sum(J13:J15) -> 51448
B17: March to May Balance | H17: Less: | J17: =sum(I18:I29) -> 18562.97
C18: 1228 | D18: 4847.78 | H18: 1931 meralco | I18: 3766.42
C19: 1127 | D19: 213.59 | H19: 1931 Assoc dues | I19: 6260.74
C20: 1230 | D20: -191.04 | H20: 635 water | I20: 1059.8
C21: 828 | D21: 4009.27 | H21: 105 water | I21: 909.4 | M21: =450*8 -> 3600
B22: Total | D22: =D18+D19+D20+D21 -> 8879.6 | H22: 105 meralco | I22: 3163.61 | M22: 1500
H23: bidet 105 | I23: 150
D24: =D22-9000 -> -120.4 | H24: bidet 635 | I24: 150
H25: grease trap | I25: 500
B26: Jun to July | I26: 500
C27: 1228 | D27: -3547.29 | E27: ='1228'!Q181 -> -8492.6 | F27: =D27-E27 -> 4945.31 | I27: 500
C28: 1127 | D28: 73.25 | E28: ='1127'!Q191 -> 73.25 | F28: =D28-E28 -> 0 | H28: Aircon | I28: 1500
C29: 1230 | D29: 3165.77 | E29: ='1230'!Q231 -> -434.23 | F29: =D29-E29 -> 3600 | H29: bulb | I29: 103
C30: 828 | D30: 1069.9 | E30: ='828'!Q199 -> 1069.902 | F30: =D30-E30 -> -0.002 | H30: Total | J30: =J16-J17 -> 32885.03
B31: Total | D31: =SUM(D27:D30) -> 761.63 | H31: 1231 internet | J31: 850
H32: Total | J32: =J30+J31 -> 33735.03
G34: April | H34: 105 | J34: ='105'!Q65 -> 0
H35: 635 | J35: ='635'!Q74 -> 0
H36: 1931 | J36: ='1931'!Q122 -> 0
B37: October 2025 to Mar 2026 | H37: Total | J37: =sum(J34:J36) -> 0
B38: 828 | C38: ='828'!Q335 -> -11828.278 | H38: 1231 internet | J38: 850
B39: 1230 | C39: ='1230'!Q415 -> -20077.93 | H39: Total | J39: =J37+J38 -> 850
B40: 1228 | C40: ='1228'!Q350 -> 21652.37 | H40: Supplies | J40: -1352.25
B41: 1127 | C41: ='1127'!Q374 -> 12397.9 | H41: Grease trap | J41: -500
B42: Total | C42: =SUM(C38:C41) -> 2144.062 | H42: MOP | J42: =-475*3 -> -1425
...

Sheet parking
C6: 9-11 | D6: D2 | E6: 800
C7: 11-12 | D7: D1 | E7: 400
C8: 15-16 | D8: k | E8: 350
C9: 16-17 | D9: D2 | E9: 400
C10: 17-18 | D10: D2 | E10: 400
C11: 19-20 | D11: D2 | E11: 400
C12: 20-22 | D12: D1 | E12: 900
C13: 22-24 | D13: T | E13: 800
C14: 24-25 | D14: T | E14: 400
C15: 25-26 | D15: P | E15: 350
C16: 26-27 | D16: D2 | E16: 400
C17: 27-28 | D17: k | E17: 350
C18: 29-1 | D18: Y | E18: 750
B19: NOV | C19: Total | E19: =sum(E6:E18) -> 6700
B23: Dec | C23: 45293 | D23: d1 | E23: 400
C24: 45355 | D24: d2 | E24: 350
C25: 4-9 | D25: M | E25: =800+900 -> 1700 | F25: early check out dec 8
C26: 45513 | D26: T | E26: 400 | F26: rebooked
C27: 45545 | D27: d2 | E27: 400
C28: 45577 | D28: d2 | E28: 700
C29: 45639 | D29: P | E29: 350
C30: 14-15 | D30: D2 | E30: 400
C31: 15-16 | D31: d2 | E31: 400
C32: 16-17 | D32: T | E32: 400
C33: 17-18 | D33: D2 | E33: 400
C34: 18-19 | D34: D2 | E34: 400
C35: 19-20 | D35: M, D1 | E35: 650
C36: 20-22 | D36: D1 | E36: 900
C37: 22-23 | D37: D2 | E37: 450
C38: 23-24 | D38: d2 | E38: 400
C39: 24-26 | D39: d2 | E39: 900
C40: 26-28 | D40: C | E40: 800
C41: 28-30 | D41: 1163 | E41: 900
C42: 30-31 | D42: d1 | E42: 400
C43: 31-1 | D43: d2 | E43: 950
B44: DEC | C44: Total | E44: =sum(E23:E43) -> 12650

Sheet Kristin
B3: ights Date Unit Amount Paid
B6: 1 | C6: Aug | D6: 13-14 | E6: P | F6: 300
B7: 2 | C7: Aug | D7: 25-27 | E7: D1 | F7: 600
B8: 1 | C8: Aug | D8: 45513 | E8: P | F8: 300
B9: 2 | C9: Aug | D9: 45546 | E9: P | F9: 600
B10: 1 | C10: Aug | D10: 45355 | E10: D3 | F10: 300
B11: 2 | C11: Aug | D11: 17-19 | E11: P | F11: 600
B12: 1 | C12: Aug | D12: 45418 | E12: M | F12: 300
B13: 1 | C13: Aug | D13: 13-14 | E13: M | F13: 300
B14: 1 | C14: Aug | D14: 17-18 | E14: M | F14: 300
B15: 1 | C15: Aug | D15: 17-18 | E15: D3 | F15: 300
B16: 1 | C16: Aug | D16: 12-13 | E16: D1 | F16: 300
B17: 1 | C17: Aug | D17: 15-16 | E17: P | F17: 300
B18: 1 | C18: Aug | D18: 20-21 | E18: P | F18: 300
B19: 2 | C19: Aug | D19: 22-24 | E19: D3 | F19: 600
B20: 1 | C20: Aug | D20: 30-31 | E20: P | F20: 300
B21: 1 | C21: Aug | D21: 31-sept | E21: M | F21: 300
B22: =SUM(B6:B21) -> 20 | C22: Total | F22: =SUM(F6:F21) -> 6000
C23: Incentive | F23: 1000
C24: Grand Total | F24: =SUM(F22:F23) -> 7000 | G24: Paid 9.1.24
C26: 1 Sept 1-2 P 300
C27: 2 Sept 4-6 D3 600

Sheet SALES NOTES
C2: SALE (1,500 for 2 nights) 1,800/ night | G2: Agents
B3: February | C3: Summer | D3: March to May
B4: July | C4: Rainy Days | D4: August | G4: Movie night / puzzles | H4: Agents | I4: SRP
B5: August | C5: Ber Month | D5: September | G5: Mon - Thurs
G6: Fri / Sun
G7: Saturday
C10: HOLIDAY RATE
C11: No lower than 2,500 | D11: December 15
C12: No lower than 2,500 | D12: Holy week
